Workbook
Name Estado_Contractual: Tablas!$C$6:$C$7
Name Moneda: Tablas!$E$6:$E$8
Name País: Tablas!$A$6:$A$21
Name Producto: Tablas!$B$6:$B$23
Name Vigencia: Tablas!$D$6:$D$44

Sheet ABM Prescription Audits
B5: ABM de Contratos
B7: País / Country: | D7: Bolivia | Q7: Fecha / Date: | R7: 45825
B10: Notificación / Notification | K10: Responsable de cuenta / KAM: | P10: RONALD CARDOZO
C12: Cliente Nuevo / New client | L12: Cliente Existente / Existing client
M13: Alta de cliente / High client
M14: Modificación - Addendum / Modification
M15: Baja-Cancelación / Cancellation
B19: Datos Contractuales / Contract data
B21: Cliente / Client: | D21: SCHMIDTS PHARMA | L21: Producto / Product: | O21: Close-Up Analyzer
B23: Fecha de Contrato / Date of contract: | G23: 45786 | L23: Estado contractual: | P23: Presupuesto aprobado
P24: Contrato Firmado
B26: Vigencia / Life: | D26: 7 meses | J26: Edición / Edition | M26: Desde: | N26: 45809 | Q26: Hasta: | R26: 45992
B30: Datos Económicos / Economic data
B32: Moneda / Currency: | D32: Dólar
E34: Contrato Anterior | J34: Contrato Actual | O34: Variación
E35: Cant. | F35: Pcio. Unit. | G35: Total Base | H35: Total Neto | J35: Cant. | K35: Pcio. Unit. | L35: Total Base | M35: Total Neto | O35: Cant. | P35: Pcio. Unit. | Q35: Total Base | R35: Total Neto | S35: %
B37: Close-Up Market | G37: =E37*F37 -> 0 | L37: =J37*K37 -> 0 | O37: =J37-E37 -> 0 | P37: =K37-F37 -> 0 | Q37: =L37-G37 -> 0 | R37: =M37-H37 -> 0 | S37: =IFERROR(R37/H37,"-") -> -
B38: Close-Up Market | G38: =G37 -> 0 | H38: =H37 -> 0 | L38: =L37 -> 0 | M38: =M37 -> 0 | Q38: =Q37 -> 0 | R38: =R37 -> 0 | S38: =IFERROR(R38/H38,"-") -> -
B40: Mercados | E40: 0 | F40: 0 | G40: =E40*F40 -> 0 | H40: =G40-(G40*0.5132) -> 0 | J40: 13 | K40: 130 | L40: =J40*K40 -> 1690 | M40: =L40-(L40*0.48) -> 878.8 | O40: =J40-E40 -> 13 | P40: =K40-F40 -> 130 | Q40: =L40-G40 -> 1690 | R40: =M40-H40 -> 878.8 | S40: =IFERROR(R40/H40,"-") -> -
B41: Regiones | E41: 0 | F41: 0 | G41: =E41*F41 -> 0 | H41: =G41-(G41*0.5132) -> 0 | J41: 6 | K41: 130 | L41: =J41*K41 -> 780 | M41: =L41-(L41*0.48) -> 405.6 | O41: =J41-E41 -> 6 | P41: =K41-F41 -> 130 | Q41: =L41-G41 -> 780 | R41: =M41-H41 -> 405.6 | S41: =IFERROR(R41/H41,"-") -> -
B42: Close-Up Targeting | G42: =SUM(G40:G41) -> 0 | H42: =SUM(H40:H41) -> 0 | L42: =SUM(L40:L41) -> 2470 | M42: =L42-(L42*0.48) -> 1284.4 | Q42: =SUM(Q40:Q41) -> 2470 | R42: =SUM(R40:R41) -> 1284.4 | S42: =IFERROR(R42/H42,"-") -> -
M43: =L43-(L43*0.48) -> 0
B44: Rep's | E44: 0 | F44: 0 | G44: =E44*F44 -> 0 | H44: =G44-(G44*0.5132) -> 0 | J44: 27 | K44: 20 | L44: =J44*K44 -> 540 | M44: =L44-(L44*0.48) -> 280.8 | O44: =J44-E44 -> 27 | P44: =K44-F44 -> 20 | Q44: =L44-G44 -> 540 | R44: =M44-H44 -> 280.8 | S44: =IFERROR(R44/H44,"-") -> -
B45: Close-Up Rep's | G45: =G44 -> 0 | H45: =H44 -> 0 | L45: =L44 -> 540 | M45: =L45-(L45*0.48) -> 280.8 | Q45: =Q44 -> 540 | R45: =R44 -> 280.8 | S45: =IFERROR(R45/H45,"-") -> -
M46: =L46-(L46*0.48) -> 0
B47: Int. Pharma Mix | M47: =L47-(L47*0.48) -> 0 | O47: =J47-E47 -> 0 | P47: =K47-F47 -> 0 | Q47: =L47-G47 -> 0 | R47: =H47-M47 -> 0 | S47: =IFERROR(R47/#REF!,"-") -> -
B48: Int. Analyzer | E48: 0 | F48: 0 | G48: =F48 -> 0 | H48: =G48-(G48*0.5132) -> 0 | J48: 1 | K48: 500 | L48: =K48 -> 500 | M48: =L48-(L48*0.48) -> 260 | O48: =J48-E48 -> 1 | P48: =K48-F48 -> 500 | Q48: =L48-G48 -> 500 | R48: =H48-M48 -> -260 | S48: =IFERROR(R48/#REF!,"-") -> -
B49: Integrador | E49: =E48 -> 0 | F49: =F48 -> 0 | G49: =G48 -> 0 | H49: =H48 -> 0 | J49: =J48 -> 1 | K49: =K48 -> 500 | L49: =L48 -> 500 | M49: =L49-(L49*0.48) -> 260 | Q49: =SUM(Q47:Q48) -> 500 | R49: =SUM(R47:R48)*-1 -> 260 | S49: =IFERROR(R49/H49,"-") -> -
M50: =L50-(L50*0.48) -> 0
B51: Hosting + Proces. | G51: =E51*F51 -> 0 | L51: =J51*K51 -> 0 | M51: =L51-(L51*0.48) -> 0 | O51: =J51-E51 -> 0 | P51: =K51-F51 -> 0 | Q51: =L51-G51 -> 0 | R51: =M51-H51 -> 0 | S51: =IFERROR(R51/H51,"-") -> -
B52: Prescriber's | G52: =SUM(G51) -> 0 | H52: =H51 -> 0 | L52: =L51 -> 0 | M52: =L52-(L52*0.48) -> 0 | Q52: =Q51 -> 0 | R52: =R51 -> 0 | S52: =IFERROR(R52/H52,"-") -> -
M53: =L53-(L53*0.48) -> 0
B54: Est. Esp. / Otros | G54: =E54*F54 -> 0 | L54: =J54*K54 -> 0 | M54: =L54-(L54*0.48) -> 0 | O54: =J54-E54 -> 0 | P54: =K54-F54 -> 0 | Q54: =L54-G54 -> 0 | R54: =M54-H54 -> 0 | S54: =IFERROR(R54/H54,"-") -> -
B55: Est. Esp. / Otros | G55: =SUM(G54) -> 0 | H55: =H54 -> 0 | L55: =L54 -> 0 | M55: =L55-(L55*0.48) -> 0 | Q55: =Q54 -> 0 | R55: =R54 -> 0 | S55: =IFERROR(R55/H55,"-") -> -
M56: =L56-(L56*0.48) -> 0
B57: Total Mensual | G57: =G38+G42+G45+G49+G52+G55 -> 0 | H57: =H38+H42+H45+H49+H52+H55 -> 0 | L57: =L38+L42+L45+L49+L52+L55 -> 3510 | M57: =L57-(L57*0.48) -> 1825.2 | Q57: =Q38+Q42+Q45+Q49+Q52+Q55 -> 3510 | R57: =R38+R42+R45+R49+R52+R55 -> 1825.2 | S57: =IFERROR(R57/H57,"-") -> -
M58: =L58-(L58*0.48) -> 0
B59: Total Anual | G59: =G57*12 -> 0 | H59: =H57*12 -> 0 | L59: =L57*7 -> 24570 | M59: =M57*7 -> 12776.4 | Q59: =Q57*7 -> 24570 | R59: =R57*7 -> 12776.4 | S59: =IFERROR(R59/H59,"-") -> -
B60: % Descuento | H60: 0 | M60: 0.48
B65: Observaciones & Motivo de cancelación / Observations & Reason for cancellation
...

Sheet e-mail Form Audits
B5: ABM de Contratos
B7: País: | C7: =INDEX('ABM Prescription Audits'!D7:G7,1,1) -> Bolivia | K7: Fecha: | L7: =INDEX('ABM Prescription Audits'!R7:S7,1,1) -> 45825
B10: Notificación | H10: Responsable de cuenta: | K10: =INDEX('ABM Prescription Audits'!P10:S10,1,1) -> RONALD CARDOZO
C12: Cliente Nuevo | H12: Cliente Existente
I13: Alta de cliente
I14: Modificación - Addendum
I15: Baja-Cancelación
B19: Datos Contractuales
B21: Cliente: | C21: SCHMIDTS PHARMA | I21: Producto: | K21: =INDEX('ABM Prescription Audits'!O21:S21,1,1) -> Close-Up Analyzer
B23: Fecha de Contrato: | D23: =INDEX('ABM Prescription Audits'!G23:I23,1,1) -> 45786 | I23: Estado: | K23: Presupuesto aprobado
K24: Contrato Firmado
B26: Vigencia: | C26: 7 meses | G26: Edición | H26: Desde: | I26: =INDEX('ABM Prescription Audits'!N26:P26,1,1) -> 45809 | K26: Hasta: | L26: 46022
B30: Datos Económicos
B32: Moneda: | C32: =INDEX('ABM Prescription Audits'!D32:G313,1,1) -> Dólar
E34: Contrato Anterior | H34: Contrato Actual | K34: Variación
E35: Total Base | F35: Total Neto | H35: Total Base | I35: Total Neto | K35: Total Base | L35: Total Neto | M35: %
B37: Close-Up Market | E37: ='ABM Prescription Audits'!G38 -> 0 | F37: ='ABM Prescription Audits'!H38 -> 0 | H37: ='ABM Prescription Audits'!L38 -> 0 | I37: ='ABM Prescription Audits'!M38 -> 0 | K37: ='ABM Prescription Audits'!Q38 -> 0 | L37: ='ABM Prescription Audits'!R38 -> 0 | M37: =IFERROR(L37/F37,"-") -> -
B39: Close-Up Targeting | E39: ='ABM Prescription Audits'!G42 -> 0 | F39: ='ABM Prescription Audits'!H42 -> 0 | H39: ='ABM Prescription Audits'!L42 -> 2470 | I39: ='ABM Prescription Audits'!M42 -> 1284.4 | K39: ='ABM Prescription Audits'!Q42 -> 2470 | L39: ='ABM Prescription Audits'!R42 -> 1284.4 | M39: =IFERROR(L39/F39,"-") -> -
B41: Close-Up Rep's | E41: ='ABM Prescription Audits'!G45 -> 0 | F41: ='ABM Prescription Audits'!H45 -> 0 | H41: ='ABM Prescription Audits'!L45 -> 540 | I41: ='ABM Prescription Audits'!M45 -> 280.8 | K41: ='ABM Prescription Audits'!Q45 -> 540 | L41: ='ABM Prescription Audits'!R45 -> 280.8 | M41: =IFERROR(L41/F41,"-") -> -
B43: Integrador | E43: ='ABM Prescription Audits'!G49 -> 0 | F43: ='ABM Prescription Audits'!H49 -> 0 | H43: ='ABM Prescription Audits'!L49 -> 500 | I43: ='ABM Prescription Audits'!M49 -> 260 | K43: ='ABM Prescription Audits'!Q49 -> 500 | L43: ='ABM Prescription Audits'!R49 -> 260 | M43: =IFERROR(L43/F43,"-") -> -
B45: Prescriber's | E45: ='ABM Prescription Audits'!G52 -> 0 | F45: ='ABM Prescription Audits'!H52 -> 0 | H45: ='ABM Prescription Audits'!L52 -> 0 | I45: ='ABM Prescription Audits'!M52 -> 0 | K45: ='ABM Prescription Audits'!Q52 -> 0 | L45: ='ABM Prescription Audits'!R52 -> 0 | M45: =IFERROR(L45/F45,"-") -> -
B47: Est. Esp. / Otros | E47: ='ABM Prescription Audits'!G55 -> 0 | F47: ='ABM Prescription Audits'!H55 -> 0 | H47: ='ABM Prescription Audits'!L55 -> 0 | I47: ='ABM Prescription Audits'!M55 -> 0 | K47: ='ABM Prescription Audits'!Q55 -> 0 | L47: ='ABM Prescription Audits'!R55 -> 0 | M47: =IFERROR(L47/F47,"-") -> -
B49: Total Mensual | E49: =E37+E39+E41+E43+E45+E47 -> 0 | F49: =F37+F39+F41+F43+F45+F47 -> 0 | H49: =H37+H39+H41+H43+H45+H47 -> 3510 | I49: =I37+I39+I41+I43+I45+I47 -> 1825.2 | K49: =K37+K39+K41+K43+K45+K47 -> 3510 | L49: =L37+L39+L41+L43+L45+L47 -> 1825.2 | M49: =IFERROR(L49/F49,"-") -> -
B51: Total Anual | E51: =E49*12 -> 0 | F51: =F49*12 -> 0 | H51: =H49*7 -> 24570 | I51: =I49*7 -> 12776.4 | K51: =K49*7 -> 24570 | L51: =L49*7 -> 12776.4 | M51: =IFERROR(L51/F51,"-") -> -
B52: % Descuento | F52: =IFERROR(F49/E49-1,0) -> 0 | I52: =IFERROR(I49/H49-1,0) -> -0.48
B57: Observaciones & Motivo de cancelación:
B58: ='ABM Prescription Audits'!B66 -> NUEVO CONTRATO
B66: Claúsulas Contractuales
B68: Renovación Automática | F68: Si | H68: No
B70: Ajuste por Inflación Anual | F70: Si | H70: No
B72: Posee Tipo de cambio fijo | F72: Si | H72: No | I72: TC Fijo
B74: Posee Tipo de cambio tope | F74: Si | H74: No | I74: TC Tope

Sheet Tablas
A2: Tablas Close-Up International
A5: País | B5: Producto | C5: Estado de Negociación | D5: Vigencia | E5: Moneda
A6: Argentina | B6: Pharma Mix | C6: Presupuesto aprobado | D6: 12 meses | E6: Dólar
A7: Brasil | B7: Pharma Mix Focus | C7: Contrato Firmado | D7: 24 meses | E7: Euro
A8: México | B8: Close-Up Analyzer | D8: 36 meses | E8: Real
A9: España | B9: Close-Up Analyzer Reps | D9: 1 mes
A10: Chile | B10: Prescriber's | D10: 2 meses
A11: Perú | B11: Regional Analyzer | D11: 3 meses
A12: Colombia | B12: Recepta | D12: 4 meses
A13: Ecuador | B13: Focus PPC | D13: 5 meses
A14: Paraguay | B14: Estudio_Especial | D14: 6 meses
A15: Uruguay | B15: Quick Data | D15: 7 meses
A16: Centroamérica | B16: Hospital Report | D16: 8 meses
A17: Bolivia | B17: Data Mart O.S. | D17: 9 meses
A18: Venezuela | B18: Close-Up Market | D18: 10 meses
A19: EEUU | B19: Close-Up Targeting | D19: 11 meses
A20: Portugal | B20: Close-Up Rep's | D20: 12 meses
A21: Suiza | B21: Integrador Pharma Mix | D21: 13 meses
B22: Integrador Analyzer | D22: 14 meses
B23: Otros | D23: 15 meses
D24: 16 meses
D25: 17 meses
D26: 18 meses
D27: 19 meses
D28: 20 meses
D29: 21 meses
D30: 22 meses
D31: 23 meses
D32: 24 meses
D33: 25 meses
D34: 26 meses
D35: 27 meses
... D44: 36 meses
