Workbook
Name as: Tablas!$D$6:$D$44
Name Cuotas: Tablas!$H$6:$H$17
Name Estado_Contractual: [1]Tablas!$C$6:$C$7
Name Estado_Contractual: Tablas!$C$6:$C$7
Name Modalidad: Tablas!$F$6:$F$13
Name Moneda: [1]Tablas!$E$6:$E$8
Name Moneda: Tablas!$E$6:$E$8
Name País: [1]Tablas!$A$6:$A$21
Name País: Tablas!$A$6:$A$21
Name Producto: [1]Tablas!$B$6:$B$23
Name Producto: Tablas!$B$6:$B$10
Name SiNo: Tablas!$G$6
Name Vigencia: [1]Tablas!$D$6:$D$44
Name Vigencia: Tablas!$D$6:$D$44

Sheet ABM Nuevos Negocios
B5: ABM de Contratos
B6: AUDITORÍA DE VENTAS
B8: País / Country: | D8: Bolivia | Q8: Fecha / Date: | R8: 45793
B11: Notificación / Notification | K11: Responsable de cuenta / KAM:
C13: Cliente Nuevo / New client | L13: Cliente Existente / Existing client
M14: Alta de Producto / Product Added
M15: Modificación - Addendum / Modification
M16: Baja-Cancelación / Cancellation
B20: Datos Contractuales / Contract data
B22: Cliente / Client: | D22: ALFA | L22: Producto / Product: | O22: CLOSE UP ACADEMY
B24: Fecha de Contrato / Date of contract: | G24: 45770 | L24: Estado contractual: | P24: Presupuesto aprobado
P25: Contrato Firmado
B27: Vigencia / Life: | D27: 1 mes | J27: Edición / Edition | M27: Desde: | N27: 45778 | Q27: Hasta:
B31: Datos Económicos / Economic data
B33: Moneda / Currency: | D33: Dólar
E35: Contrato Anterior | J35: Contrato Actual | O35: Variación
E36: Cant. | F36: Pcio. Unit. | G36: Total Base | H36: Total Neto | J36: Cant. | K36: Pcio. Unit. | L36: Total Base | M36: Total Neto | O36: Cant. | P36: Pcio. Unit. | Q36: Total Base | R36: Total Neto | S36: %
B38: Facturación recurrente
B40: Mercados | O40: =J40-E40 -> 0 | P40: =K40-F40 -> 0 | Q40: =L40-G40 -> 0 | R40: =M40-H40 -> 0 | S40: =IFERROR(R40/H40,"-") -> -
B41: RM | G41: =SUM(G40:G40) -> 0 | H41: =SUM(H40:H40) -> 0 | L41: =SUM(L40:L40) -> 0 | M41: =SUM(M40:M40) -> 0 | Q41: =SUM(Q40:Q40) -> 0 | R41: =SUM(R40:R40) -> 0 | S41: =IFERROR(R41/H41,"-") -> -
B43: Mercados | G43: =E43*F43 -> 0 | H43: =G43-G43*40% -> 0 | L43: =J43*K43 -> 0 | M43: =(L43-L43*30%) -> 0 | O43: =J43-E43 -> 0 | P43: =K43-F43 -> 0 | Q43: =L43-G43 -> 0 | R43: =M43-H43 -> 0 | S43: =IFERROR(R43/H43,"-") -> -
B44: Territorios | L44: =J44*K44 -> 0 | M44: =(L44-L44*30%) -> 0 | Q44: =O44*P44 -> 0 | R44: =M44-H44 -> 0 | S44: =IFERROR(R44/H44,"-") -> -
B45: TD | G45: =SUM(G43:G43) -> 0 | H45: =SUM(H43:H43) -> 0 | L45: =SUM(L43:L43) -> 0 | M45: =SUM(M43:M44) -> 0 | Q45: =SUM(Q43:Q43) -> 0 | R45: =SUM(R43:R44) -> 0 | S45: =IFERROR(R45/H45,"-") -> -
B47: TDD | G47: =E47*F47 -> 0 | H47: =G47-G47*0% -> 0 | L47: =J47*K47 -> 0 | M47: =L47-L47*100% -> 0 | O47: =J47-E47 -> 0 | P47: =K47-F47 -> 0 | Q47: =L47-G47 -> 0 | R47: =M47-H47 -> 0 | S47: =IFERROR(R47/H47,"-") -> -
B48: TDD | G48: =SUM(G47:G47) -> 0 | H48: =SUM(H47:H47) -> 0 | L48: =SUM(L47:L47) -> 0 | M48: =SUM(M47:M47) -> 0 | Q48: =SUM(Q47:Q47) -> 0 | R48: =SUM(R47:R47) -> 0 | S48: =IFERROR(R48/H48,"-") -> -
B50: Tipo | G50: =E50*F50 -> 0 | L50: =J50*K50 -> 0 | M50: =(L50-L50*100%)*95% -> 0 | O50: =J50-E50 -> 0 | P50: =K50-F50 -> 0 | Q50: =L50-G50 -> 0 | R50: =M50-H50 -> 0 | S50: =IFERROR(R50/H50,"-") -> -
B51: Estudio Especial | G51: =SUM(G50:G50) -> 0 | H51: =SUM(H50:H50) -> 0 | L51: =SUM(L50:L50) -> 0 | M51: =SUM(M50:M50) -> 0 | Q51: =SUM(Q50:Q50) -> 0 | R51: =SUM(R50:R50) -> 0 | S51: =IFERROR(R51/H51,"-") -> -
B53: Tipo | G53: =E53*F53 -> 0 | L53: =J53*K53 -> 0 | O53: =J53-E53 -> 0 | P53: =K53-F53 -> 0 | Q53: =L53-G53 -> 0 | R53: =M53-H53 -> 0 | S53: =IFERROR(R53/H53,"-") -> -
B54: Consultoría | G54: =SUM(G53:G53) -> 0 | H54: =SUM(H53:H53) -> 0 | L54: =SUM(L53:L53) -> 0 | M54: =SUM(M53:M53) -> 0 | Q54: =SUM(Q53:Q53) -> 0 | R54: =SUM(R53:R53) -> 0 | S54: =IFERROR(R54/H54,"-") -> -
A56: a) | B56: Total Mensual | G56: =G41+G45+G48+G51+G54 -> 0 | H56: =H41+H45+H48+H51+H54 -> 0 | L56: =L41+L45+L48+L51+L54 -> 0 | M56: =M41+M45+M48+M51+M54 -> 0 | Q56: =Q41+Q45+Q51+Q54 -> 0 | R56: =R41+R45+R48+R51+R54 -> 0 | S56: =IFERROR(R56/H56,"-") -> -
A58: a) | B58: Total Anual | G58: =G56*12 -> 0 | H58: =H56*12 -> 0 | L58: =L56*6 -> 0 | M58: =M56*8 -> 0 | Q58: =Q56*1 -> 0 | R58: =R56*1 -> 0 | S58: =IFERROR(R58/H58,"-") -> -
B59: % Descuento | H59: =IFERROR(H56/G56-1,0) -> 0
B61: Facturación esporádica (one-shot)
B63: TM | G63: =E63*F63 -> 0 | L63: =J63*K63 -> 0 | O63: =J63-E63 -> 0 | P63: =K63-F63 -> 0 | Q63: =L63-G63 -> 0 | R63: =M63-H63 -> 0 | S63: =IFERROR(R63/H63,"-") -> -
B65: TD | G65: =E65*F65 -> 0 | L65: =J65*K65 -> 0 | O65: =J65-E65 -> 0 | P65: =K65-F65 -> 0 | Q65: =L65-G65 -> 0 | R65: =M65-H65 -> 0 | S65: =IFERROR(R65/H65,"-") -> -
B67: Estudio Especial | G67: =E67*F67 -> 0 | J67: 1 | K67: 5300 | L67: =J67*K67 -> 5300 | M67: =L67-(L67*0) -> 5300 | O67: =J67-E67 -> 1 | P67: =K67-F67 -> 5300 | Q67: =L67-G67 -> 5300 | R67: =M67-H67 -> 5300 | S67: =IFERROR(R67/H67,"-") -> -
B69: Consultoría | G69: =E69*F69 -> 0 | L69: =J69*K69 -> 0 | M69: =(L69) -> 0 | Q69: =L69-G69 -> 0 | R69: =M69-H69 -> 0 | S69: =IFERROR(R69/H69,"-") -> -
A71: b) | B71: Total Anual | G71: =G63+G65+G67+G69 -> 0 | H71: =H63+H65+H67+H69 -> 0 | L71: =L63+L65+L67+L69 -> 5300 | M71: =M63+M65+M67+M69 -> 5300 | Q71: =Q63+Q65+Q67+Q69 -> 5300 | R71: =R63+R65+R67+R69 -> 5300 | S71: =IFERROR(R71/H71,"-") -> -
B72: % Descuento | H72: =IFERROR(H71/G71-1,0) -> 0 | M72: 0
B74: Total Anual (a + b) | G74: =G58+G71 -> 0 | H74: =H58+H71 -> 0 | L74: =L58+L71 -> 5300 | M74: =M58+M71 -> 5300 | Q74: =Q58+Q71 -> 5300 | R74: =R58+R71 -> 5300 | S74: =IFERROR(R74/H74,"-") -> -
...

Sheet e-mail Form Nuevos Negocios
B5: ABM de Contratos
B6: AUDITORÍA DE VENTAS
B8: País: | C8: =INDEX('ABM Nuevos Negocios'!D8:G8,1,1) -> Bolivia | K8: Fecha: | L8: 45793
B11: Notificación | H11: Responsable de cuenta: | K11: RONALD CARDOZO
C13: Cliente Nuevo | H13: Cliente Existente
I14: Alta de cliente
I15: Modificación - Addendum
I16: Baja-Cancelación
B20: Datos Contractuales
B22: Cliente: | C22: ALFA | I22: Producto: | K22: =INDEX('ABM Nuevos Negocios'!O22:S22,1,1) -> CLOSE UP ACADEMY
B24: Fecha de Contrato: | D24: 45770 | I24: Estado: | K24: Presupuesto aprobado
K25: Contrato Firmado
B27: Vigencia: | C27: =INDEX('ABM Nuevos Negocios'!D27:G27,1,1) -> 1 mes | G27: Edición | H27: Desde: | I27: =INDEX('ABM Nuevos Negocios'!N27:P27,1,1) -> 45778 | K27: Hasta:
B31: Datos Económicos
B33: Moneda: | C33: =INDEX('ABM Nuevos Negocios'!D33:G33,1,1) -> Dólar
E35: Contrato Anterior | H35: Contrato Actual | K35: Variación
E36: Total Base | F36: Total Neto | H36: Total Base | I36: Total Neto | K36: Total Base | L36: Total Neto | M36: %
B38: Facturación recurrente
B40: ='ABM Nuevos Negocios'!B41 -> RM | E40: ='ABM Nuevos Negocios'!G41 -> 0 | F40: ='ABM Nuevos Negocios'!H41 -> 0 | H40: ='ABM Nuevos Negocios'!L41 -> 0 | I40: ='ABM Nuevos Negocios'!M41 -> 0 | K40: ='ABM Nuevos Negocios'!Q41 -> 0 | L40: ='ABM Nuevos Negocios'!R41 -> 0 | M40: =IFERROR(L40/F40,"-") -> -
B42: ='ABM Nuevos Negocios'!B45 -> TD | E42: ='ABM Nuevos Negocios'!G45 -> 0 | F42: ='ABM Nuevos Negocios'!H45 -> 0 | H42: ='ABM Nuevos Negocios'!L45 -> 0 | I42: ='ABM Nuevos Negocios'!M45 -> 0 | K42: ='ABM Nuevos Negocios'!Q45 -> 0 | L42: ='ABM Nuevos Negocios'!R45 -> 0 | M42: =IFERROR(L42/F42,"-") -> -
B44: ='ABM Nuevos Negocios'!B48 -> TDD | E44: ='ABM Nuevos Negocios'!G47 -> 0 | F44: ='ABM Nuevos Negocios'!H47 -> 0 | H44: ='ABM Nuevos Negocios'!L47 -> 0 | I44: ='ABM Nuevos Negocios'!M47 -> 0 | K44: ='ABM Nuevos Negocios'!Q47 -> 0 | L44: ='ABM Nuevos Negocios'!R47 -> 0 | M44: =IFERROR(L44/F44,"-") -> -
B46: ='ABM Nuevos Negocios'!B51 -> Estudio Especial | E46: ='ABM Nuevos Negocios'!G51 -> 0 | F46: ='ABM Nuevos Negocios'!H51 -> 0 | H46: ='ABM Nuevos Negocios'!L51 -> 0 | I46: ='ABM Nuevos Negocios'!M51 -> 0 | K46: ='ABM Nuevos Negocios'!Q51 -> 0 | L46: ='ABM Nuevos Negocios'!R51 -> 0 | M46: =IFERROR(L46/F46,"-") -> -
B48: ='ABM Nuevos Negocios'!B54 -> Consultoría | E48: ='ABM Nuevos Negocios'!G53 -> 0 | F48: ='ABM Nuevos Negocios'!H54 -> 0 | H48: ='ABM Nuevos Negocios'!L54 -> 0 | I48: ='ABM Nuevos Negocios'!M54 -> 0 | K48: ='ABM Nuevos Negocios'!Q54 -> 0 | L48: ='ABM Nuevos Negocios'!R54 -> 0 | M48: =IFERROR(L48/F48,"-") -> -
A50: a) | B50: Total Mensual | E50: =E40+E42+E44+E46+E48 -> 0 | F50: =F40+F42+F44+F46+F48 -> 0 | H50: =H40+H42+H44+H46+H48 -> 0 | I50: =I40+I42+I44+I46+I48 -> 0 | K50: =K40+K42+K44+K46+K48 -> 0 | L50: =L40+L42+L44+L46+L48 -> 0 | M50: =IFERROR(L50/F50,"-") -> -
A52: a) | B52: Total Anual | E52: =E50*12 -> 0 | F52: =F50*12 -> 0 | H52: =H50*1 -> 0 | I52: =I50*1 -> 0 | K52: =K50*1 -> 0 | L52: =L50*1 -> 0 | M52: =IFERROR(L52/F52,"-") -> -
B53: % Descuento | F53: =IFERROR(F50/E50-1,0) -> 0 | I53: =IFERROR(I50/H50-1,0) -> 0
B54: Facturación esporádica (one-shot)
B57: ='ABM Nuevos Negocios'!B63 -> TM | E57: ='ABM Nuevos Negocios'!G63 -> 0 | F57: ='ABM Nuevos Negocios'!H63 -> 0 | H57: ='ABM Nuevos Negocios'!L63 -> 0 | I57: ='ABM Nuevos Negocios'!M63 -> 0 | K57: ='ABM Nuevos Negocios'!Q63 -> 0 | L57: ='ABM Nuevos Negocios'!R63 -> 0 | M57: =IFERROR(L57/F57,"-") -> -
B59: ='ABM Nuevos Negocios'!B65 -> TD | E59: ='ABM Nuevos Negocios'!G65 -> 0 | F59: ='ABM Nuevos Negocios'!H65 -> 0 | H59: ='ABM Nuevos Negocios'!L65 -> 0 | I59: ='ABM Nuevos Negocios'!M65 -> 0 | K59: ='ABM Nuevos Negocios'!Q65 -> 0 | L59: ='ABM Nuevos Negocios'!R65 -> 0 | M59: =IFERROR(L59/F59,"-") -> -
B61: ='ABM Nuevos Negocios'!B67 -> Estudio Especial | E61: ='ABM Nuevos Negocios'!G67 -> 0 | F61: ='ABM Nuevos Negocios'!H67 -> 0 | H61: ='ABM Nuevos Negocios'!L67 -> 5300 | I61: ='ABM Nuevos Negocios'!M67 -> 5300 | K61: ='ABM Nuevos Negocios'!Q67 -> 5300 | L61: ='ABM Nuevos Negocios'!R67 -> 5300 | M61: =IFERROR(L61/F61,"-") -> -
B63: ='ABM Nuevos Negocios'!B69 -> Consultoría | E63: ='ABM Nuevos Negocios'!G69 -> 0 | F63: ='ABM Nuevos Negocios'!H69 -> 0 | M63: =IFERROR(L63/F63,"-") -> -
A65: a) | B65: Total Anual | E65: =E57+E59+E61+E63 -> 0 | F65: =F57+F59+F61+F63 -> 0 | H65: =H57+H59+H61+H63 -> 5300 | I65: =I57+I59+I61+I63 -> 5300 | K65: =K57+K59+K61+K63 -> 5300 | L65: =L57+L59+L61+L63 -> 5300 | M65: =IFERROR(L65/F65,"-") -> -
B67: % Descuento | F67: =IFERROR(F65/E65-1,0) -> 0 | I67: =IFERROR(I65/H65-1,0) -> 0
B69: Total Anual (a + b) | E69: =E52+E65 -> 0 | F69: =F52+F65 -> 0 | H69: =H52+H65 -> 5300 | I69: =I52+I65 -> 5300 | K69: =K52+K65 -> 5300 | L69: =L52+L65 -> 5300 | M69: =IFERROR(L69/F69,"-") -> -
B71: Facturación en cuotas | E71: Si | F71: ='ABM Nuevos Negocios'!G77 -> 0 | G71: No | H71: ='ABM Nuevos Negocios'!I77 -> 0 | K71: Indicar cuotas | L71: ='ABM Nuevos Negocios'!Q77 -> 0
B76: Observaciones & Motivo de cancelación:
B77: ='ABM Nuevos Negocios'!B82 -> ONE SHOT
B78: ='ABM Nuevos Negocios'!B83 -> CLOSE UP ACADEMY (ORATORIA)
B84: Claúsulas Contractuales
B86: Renovación Automática | F86: Si | H86: No
...

Sheet Tablas
A2: Tablas Close-Up International
A5: País | B5: Producto | C5: Estado de Negociación | D5: Vigencia | E5: Moneda | F5: Modalidad | G5: Si/No | H5: Cuotas
A6: Argentina | B6: Consultoria | C6: Presupuesto aprobado | D6: 12 meses | E6: Dólar | F6: Blackberry by RIM | G6: x | H6: 1
A7: Brasil | B7: Publimark | C7: Contrato Firmado | D7: 24 meses | E7: Euro | F7: Android Phone | H7: 2
A8: México | B8: Pesquisa TCA – Panel | D8: 36 meses | E8: Real | F8: Android Tablets | H8: 3
A9: España | B9: Pesquisa TCA – Ad-Hoc | D9: 1 mes | F9: H5 | H9: 4
A10: Chile | B10: Otros | D10: 2 meses | F10: Ipad by Apple | H10: 5
A11: Perú | D11: 3 meses | F11: Win 32 | H11: 6
A12: Colombia | D12: 4 meses | F12: Solo Web | H12: 7
A13: Ecuador | D13: 5 meses | F13: Windows Mobile | H13: 8
A14: Paraguay | D14: 6 meses | H14: 9
A15: Uruguay | D15: 7 meses | H15: 10
A16: Centroamérica | D16: 8 meses | H16: 11
A17: Bolivia | D17: 9 meses | H17: 12
A18: Venezuela | D18: 10 meses
A19: EEUU | D19: 11 meses
A20: Portugal | D20: 12 meses
A21: Suiza | D21: 13 meses
D22: 14 meses
D23: 15 meses
D24: 16 meses
D25: 17 meses
D26: 18 meses
D27: 19 meses
D28: 20 meses
D29: 21 meses
D30: 22 meses
D31: 23 meses
D32: 24 meses
D33: 25 meses
... D44: 36 meses
