Workbook
Name Estado_Contractual: Tablas!$C$6:$C$7
Name Moneda: Tablas!$E$6:$E$8
Name País: Tablas!$A$6:$A$21
Name Producto: Tablas!$B$6:$B$23
Name Vigencia: Tablas!$D$6:$D$44

Sheet ABM Prescription Audits
B5: ABM de Contratos
B7: País / Country: | D7: Bolivia | Q7: Fecha / Date: | R7: 45797
B10: Notificación / Notification | K10: Responsable de cuenta / KAM:
C12: Cliente Nuevo / New client | L12: Cliente Existente / Existing client
M13: Alta de cliente / High client
M14: Modificación - Addendum / Modification
M15: Baja-Cancelación / Cancellation
B19: Datos Contractuales / Contract data
B21: Cliente / Client: | D21: LAQFAGAL | L21: Producto / Product: | O21: Dashboard Analyzer
B23: Fecha de Contrato / Date of contract: | G23: 45779 | L23: Estado contractual: | P23: Presupuesto aprobado
P24: Contrato Firmado
B26: Vigencia / Life: | D26: 12 meses | J26: Edición / Edition | M26: Desde: | N26: 45748 | Q26: Hasta: | R26: 46112
B30: Datos Económicos / Economic data
B32: Moneda / Currency: | D32: Dólar
E34: Contrato Anterior | J34: Contrato Actual | O34: Variación
E35: Cant. | F35: Pcio. Unit. | G35: Total Base | H35: Total Neto | J35: Cant. | K35: Pcio. Unit. | L35: Total Base | M35: Total Neto | O35: Cant. | P35: Pcio. Unit. | Q35: Total Base | R35: Total Neto | S35: %
B37: Close-Up Market | G37: =E37*F37 -> 0 | L37: =J37*K37 -> 0 | O37: =J37-E37 -> 0 | P37: =K37-F37 -> 0 | Q37: =L37-G37 -> 0 | R37: =M37-H37 -> 0 | S37: =IFERROR(R37/H37,"-") -> -
B38: Close-Up Market | G38: =G37 -> 0 | H38: =H37 -> 0 | L38: =L37 -> 0 | M38: =M37 -> 0 | Q38: =Q37 -> 0 | R38: =R37 -> 0 | S38: =IFERROR(R38/H38,"-") -> -
B40: Mercados | G40: =E40*F40 -> 0 | H40: =(G40-G40*20%)*95% -> 0 | L40: =J40*K40 -> 0 | M40: =(L40-L40*32.9%)*95% -> 0 | O40: =J40-E40 -> 0 | P40: =K40-F40 -> 0 | Q40: =L40-G40 -> 0 | R40: =M40-H40 -> 0 | S40: =IFERROR(R40/H40,"-") -> -
B41: Regiones | G41: =E41*F41 -> 0 | H41: =(G41-G41*20%)*95% -> 0 | L41: =J41*K41 -> 0 | M41: =(L41-L41*32.9%)*95% -> 0 | O41: =J41-E41 -> 0 | P41: =K41-F41 -> 0 | Q41: =L41-G41 -> 0 | R41: =M41-H41 -> 0 | S41: =IFERROR(R41/H41,"-") -> -
B42: Mercados Adicionales | G42: =E42*F42 -> 0 | H42: =(G42-G42*20%) -> 0 | L42: =J42*K42 -> 0 | M42: =(L42-L42*20%) -> 0 | O42: =J42-E42 -> 0 | P42: =K42-F42 -> 0 | Q42: =L42-G42 -> 0 | R42: =M42-H42 -> 0 | S42: =IFERROR(R42/H42,"-") -> -
B43: Close-Up Targeting | G43: =SUM(G40:G42) -> 0 | H43: =SUM(H40:H42) -> 0 | L43: =SUM(L40:L42) -> 0 | M43: =SUM(M40:M42) -> 0 | Q43: =SUM(Q40:Q42) -> 0 | R43: =SUM(R40:R42) -> 0 | S43: =IFERROR(R43/H43,"-") -> -
B45: Rep's | H45: =(G45-G45*20%)*95% -> 0 | M45: =(L45-L45*32.9%)*95% -> 0 | O45: =J45-E45 -> 0 | P45: =K45-F45 -> 0 | Q45: =L45-G45 -> 0 | R45: =M45-H45 -> 0 | S45: =IFERROR(R45/H45,"-") -> -
B46: Close-Up Rep's | G46: =G45 -> 0 | H46: =H45 -> 0 | L46: =L45 -> 0 | M46: =M45 -> 0 | Q46: =Q45 -> 0 | R46: =R45 -> 0 | S46: =IFERROR(R46/H46,"-") -> -
B48: Int. Pharma Mix | G48: =E48*F48 -> 0 | L48: =J48*K48 -> 0 | O48: =J48-E48 -> 0 | P48: =K48-F48 -> 0 | Q48: =L48-G48 -> 0 | R48: =M48-H48 -> 0 | S48: =IFERROR(R48/H48,"-") -> -
B49: Int. Analyzer | G49: =E49*F49 -> 0 | H49: =(G49-G49*20%)*95% -> 0 | L49: =J49*K49 -> 0 | M49: =(L49-L49*32.9%)*95% -> 0 | O49: =J49-E49 -> 0 | P49: =K49-F49 -> 0 | Q49: =L49-G49 -> 0 | R49: =M49-H49 -> 0 | S49: =IFERROR(R49/H49,"-") -> -
B50: Integrador | G50: =SUM(G48:G49) -> 0 | H50: =SUM(H48:H49) -> 0 | L50: =SUM(L48:L49) -> 0 | M50: =SUM(M48:M49) -> 0 | Q50: =SUM(Q48:Q49) -> 0 | R50: =SUM(R48:R49) -> 0 | S50: =IFERROR(R50/H50,"-") -> -
B52: Hosting + Proces. | G52: =E52*F52 -> 0 | H52: =G52 -> 0 | L52: =J52*K52 -> 0 | M52: =L52-L52*10% -> 0 | O52: =J52-E52 -> 0 | P52: =K52-F52 -> 0 | Q52: =L52-G52 -> 0 | R52: =M52-H52 -> 0 | S52: =IFERROR(R52/H52,"-") -> -
B53: Prescriber's | G53: =SUM(G52) -> 0 | H53: =H52 -> 0 | L53: =L52 -> 0 | M53: =M52 -> 0 | Q53: =Q52 -> 0 | R53: =R52 -> 0 | S53: =IFERROR(R53/H53,"-") -> -
B55: Est. Esp. / Otros | G55: =E55*F55 -> 0 | H55: =G55 -> 0 | L55: =J55*K55 -> 0 | O55: =J55-E55 -> 0 | P55: =K55-F55 -> 0 | Q55: =L55-G55 -> 0 | R55: =M55-H55 -> 0 | S55: =IFERROR(R55/H55,"-") -> -
B56: Est. Esp. / Otros | G56: =SUM(G55) -> 0 | H56: =H55 -> 0 | L56: =L55 -> 0 | M56: =M55 -> 0 | Q56: =Q55 -> 0 | R56: =R55 -> 0 | S56: =IFERROR(R56/H56,"-") -> -
B58: Dashboard Analyzer | E58: 0 | F58: 0 | G58: 0 | H58: 0 | J58: 1 | K58: 200 | L58: 200 | M58: 200 | O58: =J58-E58 -> 1 | P58: =K58-F58 -> 200 | Q58: =L58-G58 -> 200 | R58: =M58-H58 -> 200 | S58: =IFERROR(R58/H58,"-") -> -
B59: Dashboard Analyzer | G59: =G58 -> 0 | H59: =H58 -> 0 | L59: =L58 -> 200 | M59: =M58 -> 200 | Q59: =Q58 -> 200 | R59: =R58 -> 200 | S59: =IFERROR(R59/H59,"-") -> -
B61: Dashboard Geo-Analyzer | G61: =E61*F61 -> 0 | L61: =J61*K61 -> 0 | O61: =J61-E61 -> 0 | P61: =K61-F61 -> 0 | Q61: =L61-G61 -> 0 | R61: =M61-H61 -> 0 | S61: =IFERROR(R61/H61,"-") -> -
B62: Dashboard Geo-Analyzer | G62: =SUM(G61) -> 0 | H62: =H61 -> 0 | L62: =L61 -> 0 | M62: =M61 -> 0 | Q62: =Q61 -> 0 | R62: =R61 -> 0 | S62: =IFERROR(R62/H62,"-") -> -
B64: Total Mensual | G64: =G38+G43+G46+G50+G53+G56+G59+G62 -> 0 | H64: =H38+H43+H46+H50+H53+H56+H59+H62 -> 0 | L64: =L38+L43+L46+L50+L53+L56+L59+L62 -> 200 | M64: =M38+M43+M46+M50+M53+M56+M59+M62 -> 200 | Q64: =Q38+Q43+Q46+Q50+Q53+Q56+Q59+Q62 -> 200 | R64: =R38+R43+R46+R50+R53+R56+R59+R62 -> 200 | S64: =IFERROR(R64/H64,"-") -> -
B66: Total Anual | G66: =G64*4 -> 0 | H66: =H64*4 -> 0 | L66: =L64*12 -> 2400 | M66: =M64*12 -> 2400 | Q66: =Q64*12 -> 2400 | R66: =R64*12 -> 2400 | S66: =IFERROR(R66/H66,"-") -> -
B67: % Descuento | H67: =IFERROR(H64/G64-1,0) -> 0 | M67: =IFERROR(M64/L64-1,0) -> 0
B72: Observaciones & Motivo de cancelación / Observations & Reason for cancellation
B73: NUEVO CLIENTE RETAIL (DASHBOARDS)
...

Sheet e-mail Form Audits
B5: ABM de Contratos
B7: País: | C7: BOLIVIA | K7: Fecha: | L7: 45797
B10: Notificación | H10: Responsable de cuenta:
C12: Cliente Nuevo | H12: Cliente Existente
I13: Alta de cliente / High client
I14: Modificación - Addendum
I15: Baja-Cancelación
B19: Datos Contractuales
B21: Cliente: | C21: LAQFAGAL | I21: Producto: | K21: =INDEX('ABM Prescription Audits'!O21:S21,1,1) -> Dashboard Analyzer
B23: Fecha de Contrato: | D23: 45779 | I23: Estado: | K23: Presupuesto aprobado
K24: Contrato Firmado
B26: Vigencia: | C26: 27 meses | G26: Edición | H26: Desde: | I26: =INDEX('ABM Prescription Audits'!N26:P26,1,1) -> 45748 | K26: Hasta: | L26: =INDEX('ABM Prescription Audits'!R26:T26,1,1) -> 46112
B30: Datos Económicos
B32: Moneda: | C32: =INDEX('ABM Prescription Audits'!D32:G320,1,1) -> Dólar
E34: Contrato Anterior | H34: Contrato Actual | K34: Variación
E35: Total Base | F35: Total Neto | H35: Total Base | I35: Total Neto | K35: Total Base | L35: Total Neto | M35: %
B37: Close-Up Market | E37: ='ABM Prescription Audits'!G38 -> 0 | F37: ='ABM Prescription Audits'!H38 -> 0 | H37: ='ABM Prescription Audits'!L38 -> 0 | I37: ='ABM Prescription Audits'!M38 -> 0 | K37: ='ABM Prescription Audits'!Q38 -> 0 | L37: ='ABM Prescription Audits'!R38 -> 0 | M37: =IFERROR(L37/F37,"-") -> -
B39: Close-Up Targeting | E39: ='ABM Prescription Audits'!G43 -> 0 | F39: ='ABM Prescription Audits'!H43 -> 0 | H39: ='ABM Prescription Audits'!L43 -> 0 | I39: ='ABM Prescription Audits'!M43 -> 0 | K39: ='ABM Prescription Audits'!Q43 -> 0 | L39: ='ABM Prescription Audits'!R43 -> 0 | M39: =IFERROR(L39/F39,"-") -> -
B41: Close-Up Rep's | E41: ='ABM Prescription Audits'!G46 -> 0 | F41: ='ABM Prescription Audits'!H46 -> 0 | H41: ='ABM Prescription Audits'!L46 -> 0 | I41: ='ABM Prescription Audits'!M46 -> 0 | K41: ='ABM Prescription Audits'!Q46 -> 0 | L41: ='ABM Prescription Audits'!R46 -> 0 | M41: =IFERROR(L41/F41,"-") -> -
B43: Integrador | E43: ='ABM Prescription Audits'!G50 -> 0 | F43: ='ABM Prescription Audits'!H50 -> 0 | H43: ='ABM Prescription Audits'!L50 -> 0 | I43: ='ABM Prescription Audits'!M50 -> 0 | K43: ='ABM Prescription Audits'!Q50 -> 0 | L43: ='ABM Prescription Audits'!R50 -> 0 | M43: =IFERROR(L43/F43,"-") -> -
B45: Prescriber's | E45: ='ABM Prescription Audits'!G53 -> 0 | F45: ='ABM Prescription Audits'!H53 -> 0 | H45: ='ABM Prescription Audits'!L53 -> 0 | I45: ='ABM Prescription Audits'!M53 -> 0 | K45: ='ABM Prescription Audits'!Q53 -> 0 | L45: ='ABM Prescription Audits'!R53 -> 0 | M45: =IFERROR(L45/F45,"-") -> -
B47: Est. Esp. / Otros | E47: ='ABM Prescription Audits'!G56 -> 0 | F47: ='ABM Prescription Audits'!H56 -> 0 | H47: ='ABM Prescription Audits'!L56 -> 0 | I47: ='ABM Prescription Audits'!M56 -> 0 | K47: ='ABM Prescription Audits'!Q56 -> 0 | L47: ='ABM Prescription Audits'!R56 -> 0 | M47: =IFERROR(L47/F47,"-") -> -
B49: Dashboard Analyzer | E49: ='ABM Prescription Audits'!G56 -> 0 | F49: ='ABM Prescription Audits'!H56 -> 0 | H49: ='ABM Prescription Audits'!L56 -> 0 | I49: ='ABM Prescription Audits'!M56 -> 0 | K49: ='ABM Prescription Audits'!Q56 -> 0 | L49: ='ABM Prescription Audits'!R56 -> 0 | M49: =IFERROR(L49/F49,"-") -> -
B51: Dashboard Geo-Analyzer | E51: ='ABM Prescription Audits'!G58 -> 0 | F51: ='ABM Prescription Audits'!H58 -> 0 | H51: ='ABM Prescription Audits'!L58 -> 200 | I51: ='ABM Prescription Audits'!M58 -> 200 | K51: ='ABM Prescription Audits'!Q58 -> 200 | L51: ='ABM Prescription Audits'!R58 -> 200 | M51: =IFERROR(L51/F51,"-") -> -
B53: Total Mensual | E53: =E37+E39+E41+E43+E45+E47 -> 0 | F53: =F37+F39+F41+F43+F45+F47 -> 0 | H53: =H37+H39+H41+H43+H45+H47+H51 -> 200 | I53: =I37+I39+I41+I43+I45+I47+I51 -> 200 | K53: =K37+K39+K41+K43+K45+K47+K51 -> 200 | L53: =L37+L39+L41+L43+L45+L47+L51 -> 200 | M53: =IFERROR(L53/F53,"-") -> -
B55: Total Anual | E55: =E53*12 -> 0 | F55: =F53*12 -> 0 | H55: =H51*12 -> 2400 | I55: =I51*12 -> 2400 | K55: =K53*12 -> 2400 | L55: =L53*12 -> 2400 | M55: =IFERROR(L55/F55,"-") -> -
B56: % Descuento | F56: =IFERROR(F53/E53-1,0) -> 0 | I56: =IFERROR(I53/H53-1,0) -> 0
B61: Observaciones & Motivo de cancelación:
A62: ='ABM Prescription Audits'!B73 -> NUEVO CLIENTE RETAIL (DASHBOARDS)
A63: ='ABM Prescription Audits'!B74 -> 0
B70: Claúsulas Contractuales
B72: Renovación Automática | F72: Si | H72: No
B74: Ajuste por Inflación Anual | F74: Si | H74: No
B76: Posee Tipo de cambio fijo | F76: Si | H76: No | I76: TC Fijo
B78: Posee Tipo de cambio tope | F78: Si | H78: No | I78: TC Tope

Sheet Tablas
A2: Tablas Close-Up International
A5: País | B5: Producto | C5: Estado de Negociación | D5: Vigencia | E5: Moneda
A6: Argentina | B6: Close-Up Analyzer | C6: Presupuesto aprobado | D6: 12 meses | E6: Dólar
A7: Brasil | B7: Close-Up Analyzer Reps | C7: Contrato Firmado | D7: 24 meses | E7: Euro
A8: México | B8: Close-Up Market | D8: 36 meses | E8: Real
A9: España | B9: Close-Up Rep's | D9: 1 mes
A10: Chile | B10: Close-Up Targeting | D10: 2 meses
A11: Perú | B11: Dashboard Analyzer | D11: 3 meses
A12: Colombia | B12: Dashboard Geo-Analyzer | D12: 4 meses
A13: Ecuador | B13: Data Mart O.S. | D13: 5 meses
A14: Paraguay | B14: Estudio_Especial | D14: 6 meses
A15: Uruguay | B15: Focus PPC | D15: 7 meses
A16: Centroamérica | B16: Hospital Report | D16: 8 meses
A17: Bolivia | B17: Integrador Analyzer | D17: 9 meses
A18: Venezuela | B18: Integrador Pharma Mix | D18: 10 meses
A19: EEUU | B19: Otros | D19: 11 meses
A20: Portugal | B20: Pharma Mix | D20: 12 meses
A21: Suiza | B21: Pharma Mix Focus | D21: 13 meses
B22: Prescriber's | D22: 14 meses
B23: Quick Data | D23: 15 meses
B24: Recepta | D24: 16 meses
B25: Regional Analyzer | D25: 17 meses
D26: 18 meses
D27: 19 meses
D28: 20 meses
D29: 21 meses
D30: 22 meses
D31: 23 meses
D32: 24 meses
D33: 25 meses
D34: 26 meses
D35: 27 meses
D36: 28 meses
D37: 29 meses
... D44: 36 meses
