Workbook
Name as: Tablas!$D$6:$D$44
Name Estado_Contractual: [1]Tablas!$C$6:$C$7
Name Estado_Contractual: Tablas!$C$6:$C$7
Name Modalidad: Tablas!$F$6:$F$13
Name Moneda: [1]Tablas!$E$6:$E$8
Name Moneda: Tablas!$E$6:$E$8
Name País: [1]Tablas!$A$6:$A$21
Name País: Tablas!$A$6:$A$21
Name Producto: [1]Tablas!$B$6:$B$23
Name Producto: Tablas!$B$6:$B$14
Name Vigencia: [1]Tablas!$D$6:$D$44
Name Vigencia: Tablas!$D$6:$D$44

Sheet ABM Technology
B5: ABM de Contratos
B7: País: | D7: Bolivia | Q7: Fecha / Date: | R7: 45317
K10: Responsable de cuenta / KAM: | P10: RONALD CARDOZO
C12: Cliente Nuevo / New client | L12: Cliente Existente / Existing client
M13: Alta de Producto / Product Added
M14: Modificación - Addendum / Modification
M15: Baja-Cancelación / Cancellation
B19: Datos Contractuales / Contract data
B21: Cliente / Client: | D21: LAFAGE | L21: Producto / Product: | O21: Otros Servicios Tecnología
B23: Fecha de Contrato / Date of contract: | G23: 45001 | L23: Estado contractual: | P23: Presupuesto aprobado
P24: Contrato Firmado
B26: Vigencia / Life: | D26: 36 meses | J26: Edición / Edition | M26: Desde: | N26: 45292 | Q26: Hasta: | R26: 46054
B30: Datos Económicos / Economic data
B32: Moneda / Currency: | D32: Dólar
E34: Contrato Anterior | J34: Contrato Actual | O34: Variación
E35: Cant. | F35: Pcio. Unit. | G35: Total Base | H35: Total Neto | J35: Cant. | K35: Pcio. Unit. | L35: Total Base | M35: Total Neto | O35: Cant. | P35: Pcio. Unit. | Q35: Total Base | R35: Total Neto | S35: %
B37: Modalidad
B39: Facturación recurrente
B41: Licencia de uso | E41: 10 | F41: 45 | G41: =E41*F41 -> 450 | H41: =G41 -> 450 | J41: 10 | K41: 45 | L41: 500 | M41: =L41 -> 500 | O41: =J41-E41 -> 0 | P41: =K41-F41 -> 0 | Q41: =L41-G41 -> 50 | R41: =M41-H41 -> 50 | S41: =IFERROR(R41/M41,"-") -> 0.1
S42: =IFERROR(R42/M42,"-") -> -
B43: Hosting | H43: =G43-(G43*0.3) -> 0 | M43: =L43-(L43*0.3) -> 0 | O43: =J43-E43 -> 0 | P43: =K43-F43 -> 0 | Q43: =L43-G43 -> 0 | R43: =M43-H43 -> 0 | S43: =IFERROR(R43/M43,"-") -> -
S44: =IFERROR(R44/M44,"-") -> -
B45: Help Desk | G45: =E45*F45 -> 0 | L45: =J45*K45 -> 0 | O45: =J45-E45 -> 0 | P45: =K45-F45 -> 0 | Q45: =L45-G45 -> 0 | R45: =M45-H45 -> 0 | S45: =IFERROR(R45/M45,"-") -> -
S46: =IFERROR(R46/M46,"-") -> -
B47: Módulos adicionales | G47: =E47*F47 -> 0 | L47: =J47*K47 -> 0 | O47: =J47-E47 -> 0 | P47: =K47-F47 -> 0 | Q47: =L47-G47 -> 0 | R47: =M47-H47 -> 0 | S47: =IFERROR(R47/M47,"-") -> -
S48: =IFERROR(R48/M48,"-") -> -
B49: Otros serv. mensual | G49: =E49*F49 -> 0 | L49: =J49*K49 -> 0 | O49: =J49-E49 -> 0 | P49: =K49-F49 -> 0 | Q49: =L49-G49 -> 0 | R49: =M49-H49 -> 0 | S49: =IFERROR(R49/M49,"-") -> -
A51: a) | B51: Total Mensual | G51: =G41+G43+G45+G47+G49 -> 450 | H51: =H41+H43+H45+H47+H49 -> 450 | L51: =L41+L43+L45+L47+L49 -> 500 | M51: =M41+M43+M45+M47+M49 -> 500 | Q51: =Q41+Q43+Q45+Q47+Q49 -> 50 | R51: =R41+R43+R45+R47+R49 -> 50 | S51: =IFERROR(R51/H51,"-") -> 0.11111111
A53: a) | B53: Total Anual | G53: =G51*12 -> 5400 | H53: =H51*12 -> 5400 | L53: =L51*10 -> 5000 | M53: =M51*10 -> 5000 | Q53: =Q51*10 -> 500 | R53: =R51*10 -> 500 | S53: =IFERROR(R53/H53,"-") -> 0.092592593
B54: % Descuento | H54: =IFERROR(H51/G51-1,0) -> 0 | M54: 0
B56: Facturación esporádica
B58: Implementacion | G58: =E58*F58 -> 0 | O58: =J58-E58 -> 0 | P58: =K58-F58 -> 0 | Q58: =L58-G58 -> 0 | R58: =M58-H58 -> 0 | S58: =IFERROR(R58/H58,"-") -> -
B60: Developments (hs) | G60: =E60*F60 -> 0 | O60: =J60-E60 -> 0 | P60: =K60-F60 -> 0 | Q60: =L60-G60 -> 0 | R60: =M60-H60 -> 0 | S60: =IFERROR(R60/H60,"-") -> -
B62: Training | G62: =E62*F62 -> 0 | O62: =J62-E62 -> 0 | P62: =K62-F62 -> 0 | Q62: =L62-G62 -> 0 | R62: =M62-H62 -> 0 | S62: =IFERROR(R62/H62,"-") -> -
B64: Otros serv. anual | G64: =E64*F64 -> 0 | O64: =J64-E64 -> 0 | P64: =K64-F64 -> 0 | Q64: =L64-G64 -> 0 | R64: =M64-H64 -> 0 | S64: =IFERROR(R64/H64,"-") -> -
A66: b) | B66: Total Anual | G66: =G58+G60+G62+G64 -> 0 | H66: =H58+H60+H62+H64 -> 0 | L66: =L58+L60+L62+L64 -> 0 | M66: =M58+M60+M62+M64 -> 0 | Q66: =Q58+Q60+Q62+Q64 -> 0 | R66: =R58+R60+R62+R64 -> 0 | S66: =IFERROR(R66/H66,"-") -> -
B67: % Descuento | H67: =IFERROR(H66/G66-1,0) -> 0 | M67: 0
B69: Total Anual (a + b) | G69: =G53+G66 -> 5400 | H69: =H53+H66 -> 5400 | L69: =L53+L66 -> 5000 | M69: =M53+M66 -> 5000 | Q69: =Q53+Q66 -> 500 | R69: =R53+R66 -> 500 | S69: =IFERROR(R69/H69,"-") -> 0.092592593
B72: Forma de pago de la implementación
B73: Payment method of implementation
...

Sheet e-mail Form Technology
B5: ABM de Contratos
B7: País: | C7: BOLIVIA | K7: Fecha: | L7: =INDEX('ABM Technology'!R7:S7,1,1) -> 45317
B10: Notificación | H10: Responsable de cuenta: | K10: =INDEX('ABM Technology'!P10:S10,1,1) -> RONALD CARDOZO
C12: Cliente Nuevo | H12: Cliente Existente
I13: Alta de cliente
I14: Modificación - Addendum
I15: Baja-Cancelación
B19: Datos Contractuales
B21: Cliente: | C21: =INDEX('ABM Technology'!D21:I21,1,1) -> LAFAGE | I21: Producto: | K21: =INDEX('ABM Technology'!O21:S21,1,1) -> Otros Servicios Tecnología
B23: Fecha de Contrato: | D23: =INDEX('ABM Technology'!G23:I23,1,1) -> 45001 | I23: Estado: | K23: Presupuesto aprobado
K24: Contrato Firmado
B26: Vigencia: | C26: =INDEX('ABM Technology'!D26:G26,1,1) -> 36 meses | G26: Edición | H26: Desde: | I26: =INDEX('ABM Technology'!N26:P26,1,1) -> 45292 | K26: Hasta: | L26: 46113
B30: Datos Económicos
B32: Moneda: | C32: =INDEX('ABM Technology'!D32:G32,1,1) -> Dólar
E34: Contrato Anterior | H34: Contrato Actual | K34: Variación
E35: Total Base | F35: Total Neto | H35: Total Base | I35: Total Neto | K35: Total Base | L35: Total Neto | M35: %
B37: Modalidad | E37: =INDEX('ABM Technology'!E37:H37,1,1) -> 0 | H37: =INDEX('ABM Technology'!J37:M37,1,1) -> 0
B39: Facturación recurrente
B41: Licencia de uso | E41: ='ABM Technology'!G41 -> 450 | F41: ='ABM Technology'!H41 -> 450 | H41: ='ABM Technology'!L41 -> 500 | I41: ='ABM Technology'!M41 -> 500 | K41: ='ABM Technology'!Q41 -> 50 | L41: ='ABM Technology'!R41 -> 50 | M41: =IFERROR(L41/F41,"-") -> 0.11111111
B43: Hosting | E43: ='ABM Technology'!G43 -> 0 | F43: ='ABM Technology'!H43 -> 0 | H43: ='ABM Technology'!L43 -> 0 | I43: ='ABM Technology'!M43 -> 0 | K43: ='ABM Technology'!Q43 -> 0 | L43: ='ABM Technology'!R43 -> 0 | M43: =IFERROR(L43/F43,"-") -> -
B45: Help Desk | E45: ='ABM Technology'!G45 -> 0 | F45: ='ABM Technology'!H45 -> 0 | H45: ='ABM Technology'!L45 -> 0 | I45: ='ABM Technology'!M45 -> 0 | K45: ='ABM Technology'!Q45 -> 0 | L45: ='ABM Technology'!R45 -> 0 | M45: =IFERROR(L45/F45,"-") -> -
B47: Módulos adicionales | E47: ='ABM Technology'!G47 -> 0 | F47: ='ABM Technology'!H47 -> 0 | H47: ='ABM Technology'!L47 -> 0 | I47: ='ABM Technology'!M47 -> 0 | K47: ='ABM Technology'!Q47 -> 0 | L47: ='ABM Technology'!R47 -> 0 | M47: =IFERROR(L47/F47,"-") -> -
B49: Otros serv. mensual | E49: ='ABM Technology'!G49 -> 0 | F49: ='ABM Technology'!H49 -> 0 | H49: ='ABM Technology'!L49 -> 0 | I49: ='ABM Technology'!M49 -> 0 | K49: ='ABM Technology'!Q49 -> 0 | L49: ='ABM Technology'!R49 -> 0 | M49: =IFERROR(L49/F49,"-") -> -
A51: a) | B51: Total Mensual | E51: =E41+E43+E45+E47+E49 -> 450 | F51: =F41+F43+F45+F47+F49 -> 450 | H51: =H41+H43+H45+H47+H49 -> 500 | I51: =I41+I43+I45+I47+I49 -> 500 | K51: =K41+K43+K45+K47+K49 -> 50 | L51: =L41+L43+L45+L47+L49 -> 50 | M51: =IFERROR(L51/F51,"-") -> 0.11111111
A53: a) | B53: Total Anual | E53: =E51*12 -> 5400 | F53: =F51*12 -> 5400 | H53: =H51*10 -> 5000 | I53: =I51*10 -> 5000 | K53: =K51*10 -> 500 | L53: =L51*10 -> 500 | M53: =IFERROR(L53/F53,"-") -> 0.092592593
B54: % Descuento | F54: =IFERROR(F51/E51-1,0) -> 0 | I54: =IFERROR(I51/H51-1,0) -> 0
B56: Facturación esporádica
B59: Implementacion | E59: ='ABM Technology'!G58 -> 0 | F59: ='ABM Technology'!H58 -> 0 | H59: ='ABM Technology'!L58 -> 0 | I59: ='ABM Technology'!M58 -> 0 | K59: ='ABM Technology'!Q58 -> 0 | L59: ='ABM Technology'!R58 -> 0 | M59: =IFERROR(L59/F59,"-") -> -
B61: Developments (hs) | E61: ='ABM Technology'!G60 -> 0 | F61: ='ABM Technology'!H60 -> 0 | H61: ='ABM Technology'!L60 -> 0 | I61: ='ABM Technology'!M60 -> 0 | K61: ='ABM Technology'!Q60 -> 0 | L61: ='ABM Technology'!R60 -> 0 | M61: =IFERROR(L61/F61,"-") -> -
B63: Training | E63: ='ABM Technology'!G62 -> 0 | F63: ='ABM Technology'!H62 -> 0 | H63: ='ABM Technology'!L62 -> 0 | I63: ='ABM Technology'!M62 -> 0 | K63: ='ABM Technology'!Q62 -> 0 | L63: ='ABM Technology'!R62 -> 0 | M63: =IFERROR(L63/F63,"-") -> -
B65: Otros serv. anual | E65: ='ABM Technology'!G64 -> 0 | F65: ='ABM Technology'!H64 -> 0 | H65: ='ABM Technology'!L64 -> 0 | I65: ='ABM Technology'!M64 -> 0 | K65: ='ABM Technology'!Q64 -> 0 | L65: ='ABM Technology'!R64 -> 0 | M65: =IFERROR(L65/F65,"-") -> -
A67: a) | B67: Total Anual | E67: =E59+E61+E63+E65 -> 0 | F67: =F59+F61+F63+F65 -> 0 | H67: =H59+H61+H63+H65 -> 0 | I67: =I59+I61+I63+I65 -> 0 | K67: =K59+K61+K63+K65 -> 0 | L67: =L59+L61+L63+L65 -> 0 | M67: =IFERROR(L67/F67,"-") -> -
B69: % Descuento | F69: =IFERROR(F67/E67-1,0) -> 0 | I69: =IFERROR(I67/H67-1,0) -> 0
B71: Total Anual (a + b) | E71: =E53+E67 -> 5400 | F71: =F53+F67 -> 5400 | H71: =H53+H67 -> 5000 | I71: =I53+I67 -> 5000 | K71: =K53+K67 -> 500 | L71: =L53+L67 -> 500 | M71: =IFERROR(L71/F71,"-") -> 0.092592593
B74: Forma de pago de la implementación | G74: =INDEX('ABM Technology'!H72:J72,1,1) -> 0
B78: Observaciones & Motivo de cancelación:
B80: ='ABM Technology'!B79 -> SEGUNDO AÑO - SFNET
B88: Claúsulas Contractuales
B90: Renovación Automática | F90: Si | H90: No
B92: Ajuste por Inflación Anual | F92: Si | H92: No
...

Sheet Tablas
A2: Tablas Close-Up International
A5: País | B5: Producto | C5: Estado de Negociación | D5: Vigencia | E5: Moneda | F5: Modalidad
A6: Argentina | B6: SFNet | C6: Presupuesto aprobado | D6: 12 meses | E6: Dólar | F6: Blackberry by RIM
A7: Brasil | B7: Visilab | C7: Contrato Firmado | D7: 24 meses | E7: Euro | F7: Android Phone
A8: México | B8: Pharmaceutical BI | D8: 36 meses | E8: Real | F8: Android Tablets
A9: España | B9: Close-Up Dashboards | D9: 1 mes | F9: H5
A10: Chile | B10: Lider File NT | D10: 2 meses | F10: Ipad by Apple
A11: Perú | B11: Otros Servicios Tecnología | D11: 3 meses | F11: Win 32
A12: Colombia | B12: Software de Premiacao | D12: 4 meses | F12: Solo Web
A13: Ecuador | B13: Publimark | D13: 5 meses | F13: Windows Mobile
A14: Paraguay | B14: Otros | D14: 6 meses
A15: Uruguay | D15: 7 meses
A16: Centroamérica | D16: 8 meses
A17: Bolivia | D17: 9 meses
A18: Venezuela | D18: 10 meses
A19: EEUU | D19: 11 meses
A20: Portugal | D20: 12 meses
A21: Suiza | D21: 13 meses
D22: 14 meses
D23: 15 meses
D24: 16 meses
D25: 17 meses
D26: 18 meses
D27: 19 meses
D28: 20 meses
D29: 21 meses
D30: 22 meses
D31: 23 meses
D32: 24 meses
D33: 25 meses
... D44: 36 meses
